<?xml version='1.0'?>
<sdf version='1.6'>
  <model name='new_husky'>
    <link name='back_left_wheel'>
      <pose frame=''>-0.256 0.285475 0.035 0 -0 0</pose>
      <inertial>
        <mass>2.6357</mass>
        <pose frame=''>0 0 0 0 -0 0</pose>
        <inertia>
          <ixx>0.0246688</ixx>
          <ixy>0</ixy>
          <ixz>0</ixz>
          <iyy>0.0246688</iyy>
          <iyz>0</iyz>
          <izz>0.0441058</izz>
        </inertia>
      </inertial>
      <self_collide>0</self_collide>
      <enable_wind>0</enable_wind>
      <kinematic>0</kinematic>
      <visual name='back_left_wheel'>
        <pose frame=''>0 0 0 -3.14159 0 0</pose>
        <geometry>
          <mesh>
            <uri>model://husky/meshes/wheel.stl</uri>
          </mesh>
        </geometry>
        <material>
          <script>
            <name>Gazebo/Grey</name>
            <uri>__default__</uri>
          </script>
          <shader type='pixel'/>
        </material>
        <transparency>0</transparency>
        <cast_shadows>1</cast_shadows>
      </visual>
      <collision name='back_left_wheel_collision'>
        <laser_retro>0</laser_retro>
        <max_contacts>10</max_contacts>
        <pose frame=''>0 0 0 -1.5707 0 0</pose>
        <geometry>
          <cylinder>
            <radius>0.17775</radius>
            <length>0.1143</length>
          </cylinder>
        </geometry>
        <surface>
          <friction>
            <ode>
              <mu>100</mu>
              <mu2>100</mu2>
              <fdir1>0 0 0</fdir1>
              <slip1>0</slip1>
              <slip2>0</slip2>
            </ode>
            <torsional>
              <coefficient>1</coefficient>
              <patch_radius>0</patch_radius>
              <surface_radius>0</surface_radius>
              <use_patch_radius>1</use_patch_radius>
              <ode>
                <slip>0</slip>
              </ode>
            </torsional>
          </friction>
          <bounce>
            <restitution_coefficient>0</restitution_coefficient>
            <threshold>1e+06</threshold>
          </bounce>
          <contact>
            <collide_without_contact>0</collide_without_contact>
            <collide_without_contact_bitmask>1</collide_without_contact_bitmask>
            <collide_bitmask>1</collide_bitmask>
            <ode>
              <soft_cfm>0</soft_cfm>
              <soft_erp>0.2</soft_erp>
              <kp>1e+13</kp>
              <kd>1</kd>
              <max_vel>0.01</max_vel>
              <min_depth>0</min_depth>
            </ode>
            <bullet>
              <split_impulse>1</split_impulse>
              <split_impulse_penetration_threshold>-0.01</split_impulse_penetration_threshold>
              <soft_cfm>0</soft_cfm>
              <soft_erp>0.2</soft_erp>
              <kp>1e+13</kp>
              <kd>1</kd>
            </bullet>
          </contact>
        </surface>
      </collision>
    </link>
    <link name='back_right_wheel'>
      <pose frame=''>-0.256 -0.285475 0.035 0 -0 0</pose>
      <inertial>
        <mass>2.6357</mass>
        <pose frame=''>0 0 0 0 -0 0</pose>
        <inertia>
          <ixx>0.0246688</ixx>
          <ixy>0</ixy>
          <ixz>0</ixz>
          <iyy>0.0246688</iyy>
          <iyz>0</iyz>
          <izz>0.0441058</izz>
        </inertia>
      </inertial>
      <self_collide>0</self_collide>
      <enable_wind>0</enable_wind>
      <kinematic>0</kinematic>
      <visual name='back_right_wheel'>
        <pose frame=''>0 0 0 -3.14159 0 0</pose>
        <geometry>
          <mesh>
            <uri>model://husky/meshes/wheel.stl</uri>
          </mesh>
        </geometry>
        <material>
          <script>
            <name>Gazebo/Grey</name>
            <uri>__default__</uri>
          </script>
          <shader type='pixel'/>
          <emissive>0 0 0 1</emissive>
        </material>
        <transparency>0</transparency>
        <cast_shadows>1</cast_shadows>
      </visual>
      <collision name='back_right_wheel_collision'>
        <laser_retro>0</laser_retro>
        <max_contacts>10</max_contacts>
        <pose frame=''>0 0 0 -1.5707 0 0</pose>
        <geometry>
          <cylinder>
            <radius>0.17775</radius>
            <length>0.1143</length>
          </cylinder>
        </geometry>
        <surface>
          <friction>
            <ode>
              <mu>100</mu>
              <mu2>100</mu2>
              <fdir1>0 0 0</fdir1>
              <slip1>0</slip1>
              <slip2>0</slip2>
            </ode>
            <torsional>
              <coefficient>1</coefficient>
              <patch_radius>0</patch_radius>
              <surface_radius>0</surface_radius>
              <use_patch_radius>1</use_patch_radius>
              <ode>
                <slip>0</slip>
              </ode>
            </torsional>
          </friction>
          <bounce>
            <restitution_coefficient>0</restitution_coefficient>
            <threshold>1e+06</threshold>
          </bounce>
          <contact>
            <collide_without_contact>0</collide_without_contact>
            <collide_without_contact_bitmask>1</collide_without_contact_bitmask>
            <collide_bitmask>1</collide_bitmask>
            <ode>
              <soft_cfm>0</soft_cfm>
              <soft_erp>0.2</soft_erp>
              <kp>1e+13</kp>
              <kd>1</kd>
              <max_vel>0.01</max_vel>
              <min_depth>0</min_depth>
            </ode>
            <bullet>
              <split_impulse>1</split_impulse>
              <split_impulse_penetration_threshold>-0.01</split_impulse_penetration_threshold>
              <soft_cfm>0</soft_cfm>
              <soft_erp>0.2</soft_erp>
              <kp>1e+13</kp>
              <kd>1</kd>
            </bullet>
          </contact>
        </surface>
      </collision>
    </link>
    <link name='base_link'>
      <inertial>
        <mass>33.855</mass>
        <pose frame=''>-0.085613 -0.00084 0.238145 0 -0 0</pose>
        <inertia>
          <ixx>2.2343</ixx>
          <ixy>-0.023642</ixy>
          <ixz>0.275174</ixz>
          <iyy>3.42518</iyy>
          <iyz>0.00239624</iyz>
          <izz>2.1241</izz>
        </inertia>
      </inertial>
      <self_collide>0</self_collide>
      <enable_wind>0</enable_wind>
      <kinematic>0</kinematic>
      <pose frame=''>0 0 0 0 -0 0</pose>
      <visual name='user_rail'>
        <pose frame=''>0.272 0 0.245 0 -0 0</pose>
        <geometry>
          <mesh>
            <uri>model://husky/meshes/user_rail.stl</uri>
          </mesh>
        </geometry>
        <material>
          <script>
            <name>Gazebo/Grey</name>
            <uri>__default__</uri>
          </script>
          <shader type='pixel'/>
          <emissive>0 0 0 1</emissive>
        </material>
        <transparency>0</transparency>
        <cast_shadows>1</cast_shadows>
      </visual>
      <visual name='base'>
        <pose frame=''>0 0 0 0 -0 0</pose>
        <geometry>
          <mesh>
            <uri>model://husky/meshes/base_link.stl</uri>
          </mesh>
        </geometry>
        <material>
          <script>
            <name>Gazebo/FlatBlack</name>
            <uri>__default__</uri>
          </script>
          <shader type='pixel'/>
          <emissive>0 0 0 1</emissive>
        </material>
        <transparency>0</transparency>
        <cast_shadows>1</cast_shadows>
      </visual>
      <visual name='top_plate'>
        <pose frame=''>0 0 0 0 -0 0</pose>
        <geometry>
          <mesh>
            <uri>model://husky/meshes/top_plate.stl</uri>
          </mesh>
        </geometry>
        <material>
          <script>
            <name>Gazebo/Yellow</name>
            <uri>__default__</uri>
          </script>
          <shader type='pixel'/>
          <emissive>0 0 0 1</emissive>
        </material>
        <transparency>0</transparency>
        <cast_shadows>1</cast_shadows>
      </visual>
      <visual name='front_bumper'>
        <pose frame=''>0.47 0 0.091 0 -0 0</pose>
        <geometry>
          <mesh>
            <uri>model://husky/meshes/bumper.stl</uri>
          </mesh>
        </geometry>
        <material>
          <script>
            <name>Gazebo/FlatBlack</name>
            <uri>__default__</uri>
          </script>
          <shader type='pixel'/>
          <emissive>0 0 0 1</emissive>
        </material>
        <transparency>0</transparency>
        <cast_shadows>1</cast_shadows>
      </visual>
      <visual name='rear_bumper'>
        <pose frame=''>-0.47 0 0.091 0 -0 3.141</pose>
        <geometry>
          <mesh>
            <uri>model://husky/meshes/bumper.stl</uri>
          </mesh>
        </geometry>
        <material>
          <script>
            <name>Gazebo/FlatBlack</name>
            <uri>__default__</uri>
          </script>
          <shader type='pixel'/>
          <emissive>0 0 0 1</emissive>
        </material>
        <transparency>0</transparency>
        <cast_shadows>1</cast_shadows>
      </visual>
      <collision name='collision'>
        <laser_retro>0</laser_retro>
        <max_contacts>10</max_contacts>
        <pose frame=''>0 0 0.1 0 -0 0</pose>
        <geometry>
          <box>
            <size>1.0074 0.5709 0.2675</size>
          </box>
        </geometry>
        <surface>
          <friction>
            <ode>
              <mu>1</mu>
              <mu2>1</mu2>
              <fdir1>0 0 0</fdir1>
              <slip1>0</slip1>
              <slip2>0</slip2>
            </ode>
            <torsional>
              <coefficient>1</coefficient>
              <patch_radius>0</patch_radius>
              <surface_radius>0</surface_radius>
              <use_patch_radius>1</use_patch_radius>
              <ode>
                <slip>0</slip>
              </ode>
            </torsional>
          </friction>
          <bounce>
            <restitution_coefficient>0</restitution_coefficient>
            <threshold>1e+06</threshold>
          </bounce>
          <contact>
            <collide_without_contact>0</collide_without_contact>
            <collide_without_contact_bitmask>1</collide_without_contact_bitmask>
            <collide_bitmask>1</collide_bitmask>
            <ode>
              <soft_cfm>0</soft_cfm>
              <soft_erp>0.2</soft_erp>
              <kp>1e+13</kp>
              <kd>1</kd>
              <max_vel>0.01</max_vel>
              <min_depth>0</min_depth>
            </ode>
            <bullet>
              <split_impulse>1</split_impulse>
              <split_impulse_penetration_threshold>-0.01</split_impulse_penetration_threshold>
              <soft_cfm>0</soft_cfm>
              <soft_erp>0.2</soft_erp>
              <kp>1e+13</kp>
              <kd>1</kd>
            </bullet>
          </contact>
        </surface>
      </collision>
    </link>
    <link name='front_left_wheel'>
      <pose frame=''>0.256 0.285475 0.035 0 -0 0</pose>
      <inertial>
        <mass>2.6357</mass>
        <pose frame=''>0 0 0 0 -0 0</pose>
        <inertia>
          <ixx>0.0246688</ixx>
          <ixy>0</ixy>
          <ixz>0</ixz>
          <iyy>0.0246688</iyy>
          <iyz>0</iyz>
          <izz>0.0441058</izz>
        </inertia>
      </inertial>
      <self_collide>0</self_collide>
      <enable_wind>0</enable_wind>
      <kinematic>0</kinematic>
      <visual name='front_left_wheel'>
        <pose frame=''>0 0 0 -3.14159 0 0</pose>
        <geometry>
          <mesh>
            <uri>model://husky/meshes/wheel.stl</uri>
          </mesh>
        </geometry>
        <material>
          <script>
            <name>Gazebo/Grey</name>
            <uri>__default__</uri>
          </script>
          <shader type='pixel'/>
        </material>
        <transparency>0</transparency>
        <cast_shadows>1</cast_shadows>
      </visual>
      <collision name='front_left_wheel_collision'>
        <laser_retro>0</laser_retro>
        <max_contacts>10</max_contacts>
        <pose frame=''>0 0 0 -1.5707 0 0</pose>
        <geometry>
          <cylinder>
            <radius>0.17775</radius>
            <length>0.1143</length>
          </cylinder>
        </geometry>
        <surface>
          <friction>
            <ode>
              <mu>100</mu>
              <mu2>100</mu2>
              <fdir1>0 0 0</fdir1>
              <slip1>0</slip1>
              <slip2>0</slip2>
            </ode>
            <torsional>
              <coefficient>1</coefficient>
              <patch_radius>0</patch_radius>
              <surface_radius>0</surface_radius>
              <use_patch_radius>1</use_patch_radius>
              <ode>
                <slip>0</slip>
              </ode>
            </torsional>
          </friction>
          <bounce>
            <restitution_coefficient>0</restitution_coefficient>
            <threshold>1e+06</threshold>
          </bounce>
          <contact>
            <collide_without_contact>0</collide_without_contact>
            <collide_without_contact_bitmask>1</collide_without_contact_bitmask>
            <collide_bitmask>1</collide_bitmask>
            <ode>
              <soft_cfm>0</soft_cfm>
              <soft_erp>0.2</soft_erp>
              <kp>1e+13</kp>
              <kd>1</kd>
              <max_vel>0.01</max_vel>
              <min_depth>0</min_depth>
            </ode>
            <bullet>
              <split_impulse>1</split_impulse>
              <split_impulse_penetration_threshold>-0.01</split_impulse_penetration_threshold>
              <soft_cfm>0</soft_cfm>
              <soft_erp>0.2</soft_erp>
              <kp>1e+13</kp>
              <kd>1</kd>
            </bullet>
          </contact>
        </surface>
      </collision>
    </link>
    <link name='front_right_wheel'>
      <pose frame=''>0.256 -0.285475 0.035 0 -0 0</pose>
      <inertial>
        <mass>2.6357</mass>
        <pose frame=''>0 0 0 0 -0 0</pose>
        <inertia>
          <ixx>0.0246688</ixx>
          <ixy>0</ixy>
          <ixz>0</ixz>
          <iyy>0.0246688</iyy>
          <iyz>0</iyz>
          <izz>0.0441058</izz>
        </inertia>
      </inertial>
      <self_collide>0</self_collide>
      <enable_wind>0</enable_wind>
      <kinematic>0</kinematic>
      <visual name='front_right_wheel'>
        <pose frame=''>0 0 0 -3.14159 0 0</pose>
        <geometry>
          <mesh>
            <uri>model://husky/meshes/wheel.stl</uri>
          </mesh>
        </geometry>
        <material>
          <script>
            <name>Gazebo/Grey</name>
            <uri>__default__</uri>
          </script>
          <shader type='pixel'/>
          <emissive>0 0 0 1</emissive>
        </material>
        <transparency>0</transparency>
        <cast_shadows>1</cast_shadows>
      </visual>
      <collision name='front_right_wheel_collision'>
        <laser_retro>0</laser_retro>
        <max_contacts>10</max_contacts>
        <pose frame=''>0 0 0 -1.5707 0 0</pose>
        <geometry>
          <cylinder>
            <radius>0.17775</radius>
            <length>0.1143</length>
          </cylinder>
        </geometry>
        <surface>
          <friction>
            <ode>
              <mu>100</mu>
              <mu2>100</mu2>
              <fdir1>0 0 0</fdir1>
              <slip1>0</slip1>
              <slip2>0</slip2>
            </ode>
            <torsional>
              <coefficient>1</coefficient>
              <patch_radius>0</patch_radius>
              <surface_radius>0</surface_radius>
              <use_patch_radius>1</use_patch_radius>
              <ode>
                <slip>0</slip>
              </ode>
            </torsional>
          </friction>
          <bounce>
            <restitution_coefficient>0</restitution_coefficient>
            <threshold>1e+06</threshold>
          </bounce>
          <contact>
            <collide_without_contact>0</collide_without_contact>
            <collide_without_contact_bitmask>1</collide_without_contact_bitmask>
            <collide_bitmask>1</collide_bitmask>
            <ode>
              <soft_cfm>0</soft_cfm>
              <soft_erp>0.2</soft_erp>
              <kp>1e+13</kp>
              <kd>1</kd>
              <max_vel>0.01</max_vel>
              <min_depth>0</min_depth>
            </ode>
            <bullet>
              <split_impulse>1</split_impulse>
              <split_impulse_penetration_threshold>-0.01</split_impulse_penetration_threshold>
              <soft_cfm>0</soft_cfm>
              <soft_erp>0.2</soft_erp>
              <kp>1e+13</kp>
              <kd>1</kd>
            </bullet>
          </contact>
        </surface>
      </collision>
    </link>
    <model name='realsense_camera'>
      <plugin name='realsense_plugin' filename='librealsense_gazebo_plugin.so'/>
      <static>0</static>
      <pose frame=''>0.258342 0.01574 0.292363 0 0 0</pose>
      <link name='link'>
        <inertial>
          <mass>0.0615752</mass>
          <inertia>
            <ixx>9.108e-05</ixx>
            <ixy>0</ixy>
            <ixz>0</ixz>
            <iyy>2.51e-06</iyy>
            <iyz>0</iyz>
            <izz>8.931e-05</izz>
          </inertia>
          <pose frame=''>0 0 0 0 -0 0</pose>
        </inertial>
        <self_collide>0</self_collide>
        <enable_wind>0</enable_wind>
        <kinematic>0</kinematic>
        <gravity>1</gravity>
        <visual name='visual'>
          <geometry>
            <mesh>
              <uri>model://realsense_camera/meshes/realsense.dae</uri>
            </mesh>
          </geometry>
        </visual>
        <collision name='collision'>
          <laser_retro>0</laser_retro>
          <max_contacts>10</max_contacts>
          <pose frame=''>0 0 0 0 -0 0</pose>
          <geometry>
            <box>
              <size>0.0078 0.13 0.0192</size>
            </box>
          </geometry>
          <surface>
            <friction>
              <ode>
                <mu>1</mu>
                <mu2>1</mu2>
                <fdir1>0 0 0</fdir1>
                <slip1>0</slip1>
                <slip2>0</slip2>
              </ode>
              <torsional>
                <coefficient>1</coefficient>
                <patch_radius>0</patch_radius>
                <surface_radius>0</surface_radius>
                <use_patch_radius>1</use_patch_radius>
                <ode>
                  <slip>0</slip>
                </ode>
              </torsional>
            </friction>
            <bounce>
              <restitution_coefficient>0</restitution_coefficient>
              <threshold>1e+06</threshold>
            </bounce>
            <contact>
              <collide_without_contact>0</collide_without_contact>
              <collide_without_contact_bitmask>1</collide_without_contact_bitmask>
              <collide_bitmask>1</collide_bitmask>
              <ode>
                <soft_cfm>0</soft_cfm>
                <soft_erp>0.2</soft_erp>
                <kp>1e+13</kp>
                <kd>1</kd>
                <max_vel>0.01</max_vel>
                <min_depth>0</min_depth>
              </ode>
              <bullet>
                <split_impulse>1</split_impulse>
                <split_impulse_penetration_threshold>-0.01</split_impulse_penetration_threshold>
                <soft_cfm>0</soft_cfm>
                <soft_erp>0.2</soft_erp>
                <kp>1e+13</kp>
                <kd>1</kd>
              </bullet>
            </contact>
          </surface>
        </collision>
        <sensor name='color' type='camera'>
          <pose frame=''>0 -0.046 0.004 0 -0 0</pose>
          <camera name='__default__'>
            <horizontal_fov>1.047</horizontal_fov>
            <image>
              <width>640</width>
              <height>480</height>
              <format>RGB_INT8</format>
            </image>
            <clip>
              <near>0.1</near>
              <far>100</far>
            </clip>
            <noise>
              <type>gaussian</type>
              <mean>0</mean>
              <stddev>0.007</stddev>
            </noise>
          </camera>
          <always_on>1</always_on>
          <update_rate>60</update_rate>
          <visualize>1</visualize>
        </sensor>
        <sensor name='ired1' type='camera'>
          <pose frame=''>0 -0.06 0.004 0 -0 0</pose>
          <camera name='__default__'>
            <horizontal_fov>1.047</horizontal_fov>
            <image>
              <width>640</width>
              <height>480</height>
              <format>L_INT8</format>
            </image>
            <clip>
              <near>0.1</near>
              <far>100</far>
            </clip>
            <noise>
              <type>gaussian</type>
              <mean>0</mean>
              <stddev>0.007</stddev>
            </noise>
          </camera>
          <always_on>1</always_on>
          <update_rate>60</update_rate>
          <visualize>0</visualize>
        </sensor>
        <sensor name='ired2' type='camera'>
          <pose frame=''>0 0.01 0.004 0 -0 0</pose>
          <camera name='__default__'>
            <horizontal_fov>1.047</horizontal_fov>
            <image>
              <width>640</width>
              <height>480</height>
              <format>L_INT8</format>
            </image>
            <clip>
              <near>0.1</near>
              <far>100</far>
            </clip>
            <noise>
              <type>gaussian</type>
              <mean>0</mean>
              <stddev>0.007</stddev>
            </noise>
          </camera>
          <always_on>1</always_on>
          <update_rate>60</update_rate>
          <visualize>0</visualize>
        </sensor>
        <sensor name='depth' type='depth'>
          <pose frame=''>0 -0.03 0.004 0 -0 0</pose>
          <camera name='__default__'>
            <horizontal_fov>1.047</horizontal_fov>
            <image>
              <width>640</width>
              <height>480</height>
            </image>
            <clip>
              <near>0.1</near>
              <far>100</far>
            </clip>
            <noise>
              <type>gaussian</type>
              <mean>0</mean>
              <stddev>0.007</stddev>
            </noise>
          </camera>
          <plugin name="camera_plugin" filename="libgazebo_ros_openni_kinect.so">
            <baseline>0.2</baseline>
            <alwaysOn>true</alwaysOn>
            <!-- Keep this zero, update_rate in the parent <sensor> tag
              will control the frame rate. -->
            <updateRate>0.0</updateRate>
            <cameraName>camera_ir</cameraName>
            <imageTopicName>/camera/color/image_raw</imageTopicName>
            <cameraInfoTopicName>/camera/color/camera_info</cameraInfoTopicName>
            <depthImageTopicName>/camera/depth/image_raw</depthImageTopicName>
            <depthImageCameraInfoTopicName>/camera/depth/camera_info</depthImageCameraInfoTopicName>
            <pointCloudTopicName>/camera/depth/points</pointCloudTopicName>
            <frameName>camera_link</frameName>
            <pointCloudCutoff>0.5</pointCloudCutoff>
            <pointCloudCutoffMax>3.0</pointCloudCutoffMax>
            <distortionK1>0</distortionK1>
            <distortionK2>0</distortionK2>
            <distortionK3>0</distortionK3>
            <distortionT1>0</distortionT1>
            <distortionT2>0</distortionT2>
            <CxPrime>0</CxPrime>
            <Cx>0</Cx>
            <Cy>0</Cy>
            <focalLength>0</focalLength>
            <hackBaseline>0</hackBaseline>
          </plugin>
        </sensor>
      </link>
    </model>
    <joint name='back_left_joint' type='revolute'>
      <parent>base_link</parent>
      <child>back_left_wheel</child>
      <pose frame=''>0 0 0 0 -0 0</pose>
      <axis>
        <xyz>0 1 0</xyz>
        <use_parent_model_frame>1</use_parent_model_frame>
        <limit>
          <lower>-1e+16</lower>
          <upper>1e+16</upper>
          <effort>-1</effort>
          <velocity>-1</velocity>
        </limit>
        <dynamics>
          <spring_reference>0</spring_reference>
          <spring_stiffness>0</spring_stiffness>
          <damping>0</damping>
          <friction>0</friction>
        </dynamics>
      </axis>
      <physics>
        <ode>
          <limit>
            <cfm>0</cfm>
            <erp>0.9</erp>
          </limit>
          <suspension>
            <cfm>0</cfm>
            <erp>0.2</erp>
          </suspension>
        </ode>
      </physics>
    </joint>
    <joint name='back_right_joint' type='revolute'>
      <parent>base_link</parent>
      <child>back_right_wheel</child>
      <pose frame=''>0 0 0 0 -0 0</pose>
      <axis>
        <xyz>0 1 0</xyz>
        <use_parent_model_frame>1</use_parent_model_frame>
        <limit>
          <lower>-1e+16</lower>
          <upper>1e+16</upper>
          <effort>-1</effort>
          <velocity>-1</velocity>
        </limit>
        <dynamics>
          <spring_reference>0</spring_reference>
          <spring_stiffness>0</spring_stiffness>
          <damping>0</damping>
          <friction>0</friction>
        </dynamics>
      </axis>
      <physics>
        <ode>
          <limit>
            <cfm>0</cfm>
            <erp>0.9</erp>
          </limit>
          <suspension>
            <cfm>0</cfm>
            <erp>0.2</erp>
          </suspension>
        </ode>
      </physics>
    </joint>
    <joint name='base_link_JOINT_0' type='fixed'>
      <parent>base_link</parent>
      <child>realsense_camera::link</child>
      <pose frame=''>0 0 0 0 -0 0</pose>
      <physics>
        <ode>
          <limit>
            <cfm>0</cfm>
            <erp>0.2</erp>
          </limit>
          <suspension>
            <cfm>0</cfm>
            <erp>0.2</erp>
          </suspension>
        </ode>
      </physics>
    </joint>
    <joint name='front_left_joint' type='revolute'>
      <parent>base_link</parent>
      <child>front_left_wheel</child>
      <pose frame=''>0 0 0 0 -0 0</pose>
      <axis>
        <xyz>0 1 0</xyz>
        <use_parent_model_frame>1</use_parent_model_frame>
        <limit>
          <lower>-1e+16</lower>
          <upper>1e+16</upper>
          <effort>-1</effort>
          <velocity>-1</velocity>
        </limit>
        <dynamics>
          <spring_reference>0</spring_reference>
          <spring_stiffness>0</spring_stiffness>
          <damping>0</damping>
          <friction>0</friction>
        </dynamics>
      </axis>
      <physics>
        <ode>
          <limit>
            <cfm>0</cfm>
            <erp>0.9</erp>
          </limit>
          <suspension>
            <cfm>0</cfm>
            <erp>0.2</erp>
          </suspension>
        </ode>
      </physics>
    </joint>
    <joint name='front_right_joint' type='revolute'>
      <parent>base_link</parent>
      <child>front_right_wheel</child>
      <pose frame=''>0 0 0 0 -0 0</pose>
      <axis>
        <xyz>0 1 0</xyz>
        <use_parent_model_frame>1</use_parent_model_frame>
        <limit>
          <lower>-1e+16</lower>
          <upper>1e+16</upper>
          <effort>-1</effort>
          <velocity>-1</velocity>
        </limit>
        <dynamics>
          <spring_reference>0</spring_reference>
          <spring_stiffness>0</spring_stiffness>
          <damping>0</damping>
          <friction>0</friction>
        </dynamics>
      </axis>
      <physics>
        <ode>
          <limit>
            <cfm>0</cfm>
            <erp>0.9</erp>
          </limit>
          <suspension>
            <cfm>0</cfm>
            <erp>0.2</erp>
          </suspension>
        </ode>
      </physics>
    </joint>
    <static>0</static>
    <allow_auto_disable>1</allow_auto_disable>
    <plugin name='gps_controller' filename='libhector_gazebo_ros_gps.so'>
      <alwayson>1</alwayson>
      <updaterate>1.0</updaterate>
      <robotNamespace>/my_husky</robotNamespace>
      <bodyname>base_link</bodyname>
      <topicname>/fix</topicname>
      <velocitytopicname>/fix_velocity</velocitytopicname>
      <drift>5.0 5.0 5.0</drift>
      <gaussiannoise>0.1 0.1 0.1</gaussiannoise>
      <velocitydrift>0 0 0</velocitydrift>
      <velocitygaussiannoise>0.1 0.1 0.1</velocitygaussiannoise>
    </plugin>
    <plugin name='skid_steer_drive_controller' filename='libgazebo_ros_skid_steer_drive.so'>
      <updateRate>100.0</updateRate>
      <robotNamespace>/my_husky</robotNamespace>
      <leftFrontJoint>front_left_joint</leftFrontJoint>
      <rightFrontJoint>front_right_joint</rightFrontJoint>
      <leftRearJoint>back_left_joint</leftRearJoint>
      <rightRearJoint>back_right_joint</rightRearJoint>
      <wheelSeparation>0.5709</wheelSeparation>
      <wheelDiameter>0.3555</wheelDiameter>
      <robotBaseFrame>cam_link</robotBaseFrame>
      <torque>100</torque>
      <topicName>cmd_vel</topicName>
      <commandTopic>cmd_vel</commandTopic>
      <broadcastTF>1</broadcastTF>
    </plugin>
  </model>
</sdf>
